Workbook

Sheet Product_Backlog
A1: ID Epica | B1: Épica | C1: ID Historia de usuario | D1: Historia de Usuario | E1: Descripción | H1: Horas estimadas | I1: Prioridad
A2: E01 | B2: Facilitar el acceso seguro y la gestión de cuentas de los usuarios | C2: HU-AU-01 | D2: Registro de usuario | E2: Como vecino quiero registrarme con un formulario básico de mis datos, para poder acceder al sistema. | H2: 3 | I2: 5
A3: E01 | C3: HU-AU-02 | D3: Inicio de sesión | E3: Como usuario quiero iniciar sesión con mis credenciales, para acceder a mis funcionalidades. | H3: 2 | I3: 5
A4: E01 | C4: HU-AU-03 | D4: Restablecer contraseña | E4: Como usuario quiero restablecer mi contraseña olvidada, para recuperar el acceso a mi cuenta. | H4: 3 | I4: 3
A5: E01 | C5: HU-AU-04 | D5: Cambio de contraseña | E5: Como usuario quiero cambiar mi contraseña, para mantener segura mi cuenta. | H5: 2 | I5: 3
A6: E02 | B6: Gestión de usuarios | C6: HU-GU-01 | D6: Crear cuenta de usuario | E6: Como admin quiero crear cuentas de usuario (directiva/personal autorizado), para dar acceso y permisos al sistema. | H6: 2 | I6: 5
A7: E02 | B7: Gestión de usuarios | C7: HU-GU-02 | D7: Editar datos de usuario | E7: Como usuario quiero editar los datos de mi cuenta, para mantener mi información actualizada. | H7: 2 | I7: 3
A8: E02 | B8: Gestión de usuarios | C8: HU-GU-03 | D8: Desactivar/activar cuenta | E8: Como admin quiero desactivar temporalmente una cuenta, para impedir accesos sin eliminarla o en su defecto, activar una cuenta que ha sido desactivada. | H8: 2 | I8: 3
A9: E02 | B9: Gestión de usuarios | C9: HU-GU-04 | D9: Desactivar/activar | E9: Como usuario quiero desactivar temporalmente o activar mi cuenta volviendo a iniciar sesión. | H9: 2 | I9: 3
A10: E02 | B10: Gestión de usuarios | C10: HU-GU-05 | D10: Listado de usuarios | E10: Como admin quiero ver un listado de usuarios registrado en el sistema, para gestionarlos fácilmente. | H10: 2 | I10: 3
A11: E03 | B11: Certificados de residencia | C11: HU-CR-01 | D11: Solicitar certificado | E11: Como socio quiero acceder a un apartado especial de certificados en línea, para poder iniciar el trámite de manera digital. | H11: 3 | I11: 5
A12: E03 | B12: Certificados de residencia | C12: HU-CR-02 | D12: Completar formulario de certificado | E12: Como socio quiero rellenar un formulario con mis datos básicos (nombre, RUT, dirección), para solicitar mi certificado de residencia. | H12: 2 | I12: 5
A13: E03 | B13: Certificados de residencia | C13: HU-CR-03 | D13: Validación de datos | E13: Como sistema quiero validar automáticamente los datos ingresados en el formulario, para asegurar que la información es correcta antes de emitir el certificado. | H13: 3 | I13: 5
A14: E03 | B14: Certificados de residencia | C14: HU-CR-04 | D14: Pago del certificado | E14: Como socio quiero ser redirigido al sistema de pagos después de validar mis datos, para completar el trámite del certificado. | H14: 5 | I14: 5
A15: E03 | B15: Certificados de residencia | C15: HU-CR-05 | D15: Emisión de certificado | E15: Como sistema quiero emitir el certificado de residencia automáticamente una vez confirmado el pago, para que quede registrado en la base de datos. | H15: 3 | I15: 5
A16: E03 | B16: Certificados de residencia | C16: HU-CR-06 | D16: Descarga del certificado en PDF | E16: Como socio quiero descargar mi certificado aprobado en formato PDF, para presentarlo en trámites oficiales. | H16: 2 | I16: 5
A17: E04 | B17: Reservas de espacios comunitarios | C17: HU-RE-01 | D17: Reservar espacio comunitario | E17: Como socio quiero seleccionar un espacio comunitario y un horario disponible, para reservarlo en actividades. | H17: 3 | I17: 4
... A43: E09 | B43: Registro de errores | C43: HU-ER-04 | D43: Registro y trazabilidad de errores | E43: Como directiva quiero llevar un registro de cualquier error que ocurra en el sistema (solicitudes, pagos, reservas, etc.), para poder dar seguimiento y saber si ya fue gestionado o no. | H43: 1 | I43: 2

Sheet Product_Backlog_
A1: ID Epica | B1: Épica | C1: ID Historia de usuario | D1: Historia de Usuario | E1: Descripción | F1: Criterios de aceptacion | G1: Prioridad
A2: E01 | B2: Facilitar el registro, inicio de sesión y gestión de cuentas de los usuarios | C2: HU-AUG-01 | D2: Registro de usuario (Socio) | E2: Como vecino quiero registrarme con un formulario básico de mis datos, para poder acceder al sistema. | F2: - El formulario de registro debe incluir campos para nombre completo, RUT, dirección y correo electrónico. - El sistema debe validar que el RUT ingresado sea válido. - El usuario debe recibir un correo de confirmación con un enlace para activar su cuenta. - El registro debe crear una cuenta de usuario activa que permita al usuario iniciar sesión inmediatamente después de la confirmación. | G2: Must Have
A3: E01 | C3: HU-AUG-02 | D3: Inicio de sesión | E3: Como usuario quiero iniciar sesión con mis credenciales, para acceder a mis funcionalidades. | F3: - El sistema debe permitir al usuario iniciar sesión utilizando su correo electrónico y contraseña. - El sistema debe mostrar un mensaje de error si las credenciales no coinciden. - El sistema debe redirigir al usuario a su panel de usuario después de un inicio de sesión exitoso. | G3: Must Have | J3: Must have Impresindible | K3: Las historias de "Must Have" son las que definen la funcionalidad básica e indispensable del sistema. Sin ellas, el proyecto no puede operar.
A4: E01 | C4: HU-AUG-03 | D4: Restablecer contraseña | E4: Como usuario quiero restablecer mi contraseña olvidada, para recuperar el acceso a mi cuenta. | F4: - El sistema debe ofrecer una opción de "¿Olvidaste tu contraseña?" en la página de inicio de sesión. - El sistema debe enviar un correo electrónico con un enlace para restablecer la contraseña. - El enlace debe redirigir al usuario a una página de restablecimiento donde pueda ingresar y confirmar una nueva contraseña. | G4: Should Have | J4: Should have Deberia Tener | K4: Las historias de "Should Have" son importantes para el funcionamiento completo del sistema, pero pueden ser implementadas después del MVP.
A5: E01 | C5: HU-AUG-04 | D5: Cambio de contraseña | E5: Como usuario quiero cambiar mi contraseña, para mantener segura mi cuenta. | F5: - El usuario debe poder cambiar su contraseña desde la página de configuración de su cuenta. - El sistema debe validar que la nueva contraseña cumpla con los requisitos de seguridad (mínimo 8 caracteres, incluyendo números y letras). - El sistema debe mostrar un mensaje de confirmación cuando el cambio de contraseña sea exitoso. | G5: Should Have | J5: Could have Podria Tener | K5: Las historias de "Could Have" son deseables y mejoran la experiencia del usuario, pero no son esenciales para la primera versión del sistema.
A6: E01 | C6: HU-AUG-05 | D6: Crear cuenta de usuario (Sistema) | E6: Como admin quiero crear cuentas de usuario (directiva/personal autorizado), para dar acceso y permisos al sistema. | F6: - El admin debe poder crear una cuenta de usuario desde el panel de administración. - El admin debe asignar un rol a cada usuario (directiva, personal autorizado). - El usuario debe recibir un correo de bienvenida con las credenciales iniciales para acceder al sistema. | G6: Must Have
A7: E01 | C7: HU-AUG-06 | D7: Editar datos de usuario (Sistema) | E7: Como usuario quiero editar los datos de mi cuenta, para mantener mi información actualizada. | F7: - El usuario debe poder modificar su nombre, dirección y correo electrónico. - El sistema debe validar que el correo electrónico ingresado sea único. - Los cambios deben reflejarse inmediatamente en la base de datos y ser visibles en el perfil del usuario | G7: Should Have
A8: E01 | C8: HU-AUG-07 | D8: Desactivar/activar usuario (Sistema) | E8: Como admin quiero desactivar temporalmente una cuenta, para impedir accesos sin eliminarla o en su defecto, activar una cuenta que ha sido desactivada. | F8: - El admin debe poder desactivar temporalmente una cuenta desde el panel de administración. - El usuario desactivado no podrá iniciar sesión hasta que su cuenta sea reactivada. - El admin debe poder reactivar la cuenta desde el mismo panel de administración. | G8: Should Have
A9: E01 | C9: HU-AUG-08 | D9: Desactivar/activar cuenta | E9: Como usuario/vecino quiero desactivar temporalmente o activar mi cuenta volviendo a iniciar sesión. | F9: - El usuario debe poder desactivar temporalmente su cuenta desde su panel de configuración. - El usuario desactivado debe ser notificado de que su cuenta ha sido desactivada con éxito. - El usuario debe poder reactivar su cuenta al iniciar sesión con sus credenciales. | G9: Should Have
A10: E01 | C10: HU-AUG-09 | D10: Listado de usuarios | E10: Como admin quiero ver un listado de usuarios registrado en el sistema, para gestionarlos fácilmente. | F10: - El admin debe ver un listado completo de usuarios registrados. - El listado debe incluir nombre, rol y estado de cada cuenta (activa o desactivada). - El admin debe poder filtrar usuarios por estado (activo, desactivado). | G10: Should Have
A11: E02 | B11: Facilitar la gestión de certificados de residencia | C11: HU-CR-01 | D11: Solicitar certificado | E11: Como socio quiero acceder a un apartado especial de certificados en línea, para poder iniciar el trámite de manera digital. | F11: - El socio debe tener acceso a un apartado especial para solicitar certificados. - El sistema debe mostrar una opción de selección de tipo de certificado. - El usuario debe poder iniciar el trámite directamente desde su cuenta. | G11: Must Have
A12: E02 | C12: HU-CR-02 | D12: Completar formulario de certificado | E12: Como socio quiero rellenar un formulario con mis datos básicos (nombre, RUT, dirección), para solicitar mi certificado de residencia. | F12: - El formulario debe requerir los campos nombre, RUT, dirección del socio. - El sistema debe validar que los campos estén completos antes de permitir el envío del formulario. - El sistema debe mostrar un mensaje de confirmación una vez que el formulario sea completado correctamente. | G12: Must Have
A13: E02 | C13: HU-CR-03 | D13: Validación de datos | E13: Como sistema quiero validar automáticamente los datos ingresados en el formulario, para asegurar que la información es correcta antes de emitir el certificado. | F13: - El sistema debe validar automáticamente que los datos ingresados son correctos (ej. RUT válido, formato correcto de dirección). - El sistema debe mostrar un mensaje de error si alguno de los datos es incorrecto. - Si los datos son correctos, el sistema debe proceder al siguiente paso de pago. | G13: Should Have
A14: E02 | C14: HU-CR-04 | D14: Pago del certificado | E14: Como socio quiero ser redirigido al sistema de pagos después de validar mis datos, para completar el trámite del certificado. | F14: - El sistema debe redirigir al usuario a un sistema de pago seguro después de la validación de datos. - El sistema debe permitir el pago mediante tarjetas de crédito, débito o plataformas en línea. - El pago debe ser validado antes de proceder a la emisión del certificado. | G14: Must Have
A15: E02 | C15: HU-CR-05 | D15: Emisión de certificado | E15: Como sistema quiero emitir el certificado de residencia automáticamente una vez confirmado el pago, para que quede registrado en la base de datos. | F15: - El sistema debe generar el certificado de residencia automáticamente después de recibir la confirmación de pago. - El certificado debe ser registrado en la base de datos del sistema. - El sistema debe permitir la descarga del certificado en formato PDF. | G15: Must Have
A16: E02 | C16: HU-CR-06 | D16: Descarga del certificado en PDF | E16: Como socio quiero descargar mi certificado aprobado en formato PDF, para presentarlo en trámites oficiales. | F16: - El sistema debe permitir al socio descargar el certificado en formato PDF tras la emisión. - El certificado descargado debe tener un formato estándar que contenga todos los datos validados. | G16: Should Have
C17: HU-CR-07 | D17: Visualizar certificados emitidos por usuario | E17: Como socio quiero poder visualizar el historial de certificados que he solicitado a la junta de vecinos, tener un registro de mis certificados emitidos. | F17: - El sistema debe mostrar un listado con todos los certificados emitidos asociados al socio. - El sistema debe mostrar todos los certificados filtrados por fecha de emisión.
C18: HU-CR-08 | D18: Descargar último certificado emitido | E18: Como socio quiero poder descargar el último certificado de residencia emitido para poder descargarlo en caso de necesitarlo nuevamente | F18: - El sistema debe identificar automáticamente el certificado de residencia más reciente del socio. - El sistema debe permitir la descarga del último certificado emitido en formato PDF. - Si no existe un certificado emitido disponible, el sistema debe mostrar un mensaje informativo.
A19: E03 | B19: Optimizar la gestión de reservas de espacios comunitarios | C19: HU-RE-01 | D19: Reservar espacio comunitario | E19: Como socio quiero seleccionar un espacio comunitario y un horario disponible, para reservarlo en actividades. | F19: - El socio debe poder seleccionar un espacio y horario disponible para hacer la reserva. - El sistema debe mostrar un calendario con los horarios disponibles. - El sistema debe confirmar la reserva inmediatamente después de que el socio haya seleccionado el espacio. | G19: Must Have
A20: E03 | C20: HU-RE-02 | D20: Evitar reservas duplicadas | E20: Como sistema quiero impedir reservas en horarios ya ocupados, para evitar conflictos. | F20: - El sistema debe impedir que un espacio ya reservado se pueda seleccionar nuevamente en el mismo horario. - El sistema debe mostrar un mensaje de error si el socio intenta reservar un espacio ya ocupado. | G20: Should Have
A21: E03 | C21: HU-RE-03 | D21: Pago de la reserva | E21: Como socio quiero ser redirigido al sistema de pago después de seleccionar el espacio, para confirmar la reserva cuando tenga costo asociado. | F21: - El sistema debe redirigir al socio a un sistema de pago seguro después de seleccionar el espacio. - El sistema debe permitir el pago mediante tarjetas de crédito, débito o plataformas en línea. - El pago debe ser validado antes de confirmar la reserva. | G21: Must Have
A22: E03 | C22: HU-RE-04 | D22: Confirmación automática de reserva | E22: Como sistema quiero confirmar la reserva automáticamente solo si el pago fue validado (cuando aplique), para garantizar que la reserva esté asegurada. | F22: - El sistema debe confirmar automáticamente la reserva solo si el pago fue validado con éxito. - El sistema debe enviar una notificación por correo electrónico al socio confirmando la reserva. | G22: Should Have
A23: E03 | C23: HU-RE-05 | D23: Visualizar Reservas por usuario | E23: Como socio quiero poder visualizar mis últimas 3 reservas realizadas para poder llevar un registro de estas. | F23: - El sistema debe mostrar un listado con las últimas 3 reservas realizadas por el socio. - El sistema debe mostrar información básica de cada reserva (fecha, espacio reservado y estado). - Si el usuario no tiene reservas, el sistema debe mostrar un mensaje informativo. | G23: Should Have
A24: E03 | C24: HU-RE-06 | D24: Editar espacio comunitario | E24: Como usuario directiva/admin quiero poder editar un espacio comunitario para poder actualizar la información en casos necesarios. | F24: - El sistema debe permitir al usuario directiva/admin editar los datos del espacio comunitario (nombre, descripción, capacidad, horarios, etc.). - El sistema debe validar que los campos editados cumplan con los formatos requeridos antes de guardar los cambios. - El sistema debe mostrar un mensaje de confirmación al guardar la información actualizada.
C25: HU-RE-07 | D25: Crear espacio comunitario | E25: Como usuario directiva/admin quiero poder crear un espacio comunitario para que estos estén disponibles para que los vecinos puedan arrendarlos. | F25: - El sistema debe permitir al usuario directiva/admin ingresar los datos necesarios para crear un nuevo espacio comunitario. - El sistema debe validar que todos los campos requeridos estén completos antes de crear el espacio. - El sistema debe mostrar un mensaje de confirmación una vez creado el nuevo espacio comunitario.
C26: HU-RE-08 | D26: Eliminar espacio comunitario | E26: Como usuario directiva/admin quiero poder eliminar un espacio comunitario para que estos ya no esten disponibles para su arriendo. | F26: - El sistema debe permitir al usuario directiva/admin seleccionar un espacio comunitario para eliminarlo. - El sistema debe solicitar una confirmación antes de eliminar el espacio definitivamente. - El sistema debe mostrar un mensaje informativo indicando que el espacio fue eliminado correctamente.
A27: E04 | B27: Facilitar la visualización de noticias y comunicación comunitaria | C27: HU-NA-01 | D27: Visualizar noticias | E27: Como vecino quiero ver las noticias de la comuna o el país. | F27: - El vecino debe poder ver todas las noticias publicadas en la página de inicio o sección de noticias. - Las noticias deben estar ordenadas por fecha, mostrando las más recientes primero. - Cada noticia debe permitir ver más detalles y contener un enlace a información adicional. | G27: Could Have
A28: E04 | C28: HU-NA-02 | D28: Noticias desde API externa | E28: Como sistema quiero traer noticias desde la API externa, para mantenerlas actualizadas. | F28: - El sistema debe integrar una API externa para traer noticias actualizadas de fuentes externas (ej. RSS o similar). - Las noticias obtenidas deben ser automáticamente publicadas en el sistema. - El sistema debe mostrar un mensaje de error si no se pueden obtener noticias de la API. | G28: Could Have
A29: E05 | B29: Asegurar un procesamiento de pagos seguro y eficiente | C29: HU-PG-01 | D29: Integración con pasarela de pago | E29: Como sistema quiero integrarme con una pasarela de pago vía API REST/JSON sobre HTTPS, para procesar cobros de forma segura. | F29: - El sistema debe integrarse correctamente con una pasarela de pago (como Transbank) usando API REST/JSON sobre HTTPS. - El sistema debe ser capaz de procesar pagos de manera segura y cifrada. - La pasarela debe validar los pagos correctamente y confirmar su éxito o fallo. | G29: Must Have
A30: E05 | C30: HU-PG-02 | D30: Checkout seguro y retorno | E30: Como socio quiero ser redirigido a un checkout seguro de la pasarela y, al finalizar, volver al sistema con el resultado del pago, para completar mi trámite. | F30: - El socio debe ser redirigido a un checkout seguro para procesar el pago. - Al finalizar el pago, el socio debe ser redirigido de vuelta al sistema con el estado del pago (aprobado, rechazado, cancelado). - El sistema debe notificar al usuario sobre el resultado del pago de manera clara. | G30: Must Have
A31: E05 | C31: HU-PG-03 | D31: Actualización por webhook/callback | E31: Como sistema quiero actualizar el estado del pago a `APPROVED`, `REJECTED` o `CANCELED` cuando reciba el webhook/callback de la pasarela, para reflejar el resultado real. | F31: - El sistema debe actualizar el estado del pago en tiempo real cuando reciba el webhook/callback de la pasarela de pago. - Los estados que deben actualizarse son: APPROVED, REJECTED y CANCELED. - El sistema debe reflejar el estado real del pago en el sistema de reservas o certificados. | G31: Must Have
A32: E05 | C32: HU-PG-04 | D32: Confirmación automática condicionada al pago | E32: Como sistema quiero confirmar automáticamente la solicitud/reserva solo si el pago queda en estado `APPROVED`, para garantizar que el servicio está cubierto. | F32: - El sistema debe confirmar automáticamente la solicitud o reserva solo si el pago es aprobado. - El sistema debe enviar una notificación al usuario con el estado de su solicitud o reserva. | G32: Must Have
A33: E05 | C33: HU-PG-05 | D33: Comprobante digital | E33: Como socio quiero recibir/descargar un comprobante digital del pago realizado, para tener respaldo de mi transacción. | F33: - El socio debe poder descargar un comprobante digital en formato PDF del pago realizado. - El comprobante debe incluir detalles del pago: monto, fecha, método de pago y número de transacción. - El sistema debe enviar un correo con el comprobante al socio después de completar la transacción. | G33: Must Have
A34: E06 | B34: Optimizar la gestión y control administrativo de la junta de vecinos | C34: HU-RPE-01 | D34: Reporte de socios activos | E34: Como directiva quiero visualizar un reporte de socios activos, para tener control de la comunidad. | F34: - La directiva debe poder generar un reporte de socios activos, mostrando el nombre, RUT y estado de cada socio. - El reporte debe poder ser exportado en formato PDF o Excel. - El sistema debe mostrar un mensaje de error si no hay datos disponibles para el reporte. | G34: Should Have
A35: E06 | C35: HU-RPE-02 | D35: Reportes de reservas | E35: Como directiva quiero visualizar un reporte de la cantidad e ingresos de todas las reservas de mi junta de vecinos para llevar un registro de estas. | F35: - El sistema debe generar un reporte que muestre la cantidad total de reservas realizadas en un período definido. - El sistema debe mostrar el total de ingresos generados por las reservas. - El sistema debe mostrar un mensaje informativo en caso de no haber registros. | G35: Should Have
A36: E06 | C36: HU-RPE-03 | D36: Reportes de certificados emitidos | E36: Como directiva quiero visualizar un reporte de la cantidad e ingresos de todos los certificados de residencia emitidos de mi junta de vecinos para llevar un registro de estos. | F36: - El sistema debe generar un reporte con la cantidad de certificados de residencia emitidos en un período definido. - El sistema debe mostrar el total de ingresos generados por los certificados emitidos. - El sistema debe mostrar un mensaje informativo en caso de no haber registros. | G36: Should Have
A37: E06 | C37: HU-RPE-04 | D37: Exportar reportes | E37: Como directiva quiero exportar reportes en PDF/Excel, para compartirlos fácilmente. | F37: - La directiva debe poder exportar los reportes de socios, reservas y certificados en formatos PDF o Excel. - El sistema debe mostrar una opción de exportación en la interfaz de reportes. | G37: Should Have
A38: E06 | C38: HU-RPE-05 | D38: Filtro reportes por mes | E38: Como directiva quiero filtrar los reportes por mes para obtener información específica del período que necesito analizar. | F38: - El sistema debe permitir seleccionar un mes y año para filtrar los reportes. - El sistema debe actualizar automáticamente la información mostrada según el mes seleccionado. - El sistema debe mostrar un mensaje informativo si no existen datos disponibles para el período filtrado. | G38: Should Have
A39: E06 | C39: HU-RPE-06 | D39: Distribución de espacios reservados | E39: Como directiva quiero visualizar la distribución de los espacios comunitarios más reservados para entender cuáles tienen mayor demanda y tomar decisiones de gestión. | F39: - El sistema debe generar un gráfico con la distribución de reservas por cada espacio comunitario. - El sistema debe mostrar la cantidad total de reservas por espacio en forma visual (ej. gráfico de barras o torta). - El sistema debe mostrar un mensaje informativo si no existen datos disponibles | G39: Could Have
A40: E06 | C40: HU-RPE-07 | D40: Reporte de ingresos totales | E40: Como directiva quiero visualizar un reporte de los ingresos totales generados por reservas y certificados para tener un control financiero general de la junta de vecinos. | F40: - El sistema debe mostrar el total de ingresos sumando certificados emitidos y reservas realizadas. - El sistema debe mostar un grafico comparativo entre reservas y emisión de certificados. - El sistema debe mostrar un mensaje informativo si no existen datos disponibles | G40: Should Have
...

Sheet Product_Backlog_tareas
B1: Resultado de la actividad Sprint Planning
B2: Sprint Backlog con estimación de tareas para las historia de usuario del Primer Sprint
B4: Total Horas: | D4: =SUM(E8:E133) -> 102
B5: Total Semanas | D5: 2
A7: ID Epica | B7: ID Historia | C7: ID Tarea | D7: Tareas o actividad | E7: Horas estimadas
A8: E01 | B8: HU-AUG-01 | C8: =CONCATENATE($A$8,"-",B8,"-","T1") -> E01-HU-AUG-01-T1 | D8: Diseñar y validar el formulario de registro (campos: nombre, RUT, dirección, correo) | E8: 6 | F8: SPRINT 1
C9: =CONCATENATE($A$8,"-",B8,"-","T2") -> E01-HU-AUG-01-T2 | D9: Implementar la validación del RUT y correo electrónico para evitar errores. | E9: 8
C10: =CONCATENATE($A$8,"-",B8,"-","T3") -> E01-HU-AUG-01-T3 | D10: Desarrollar la funcionalidad para enviar un correo de confirmación con el enlace de activación. | E10: 10
B11: HU-AUG-02 | C11: =CONCATENATE($A$8,"-",B11,"-","T1") -> E01-HU-AUG-02-T1 | D11: Crear el formulario de inicio de sesión con campos para correo y contraseña. | E11: 4
C12: =CONCATENATE($A$8,"-",B11,"-","T2") -> E01-HU-AUG-02-T2 | D12: Implementar la validación de credenciales en el backend. | E12: 8
C13: =CONCATENATE($A$8,"-",B11,"-","T3") -> E01-HU-AUG-02-T3 | D13: Crear la lógica para redirigir a los usuarios al panel de usuario tras un inicio de sesión exitoso | E13: 6
B14: HU-AUG-03 | C14: =CONCATENATE($A$8,"-",B14,"-","T1") -> E01-HU-AUG-03-T1 | D14: Implementar el formulario de restablecimiento de contraseña con un campo de correo. | F14: SPRINT 3
C15: =CONCATENATE($A$8,"-",B14,"-","T2") -> E01-HU-AUG-03-T2 | D15: Configurar el envío de un correo de restablecimiento con un enlace seguro.
C16: =CONCATENATE($A$8,"-",B14,"-","T3") -> E01-HU-AUG-03-T3 | D16: Crear la página donde el usuario puede ingresar su nueva contraseña.
B17: HU-AUG-04 | C17: =CONCATENATE($A$8,"-",B17,"-","T1") -> E01-HU-AUG-04-T1 | D17: Desarrollar el formulario de cambio de contraseña dentro del perfil del usuario.
C18: =CONCATENATE($A$8,"-",B17,"-","T2") -> E01-HU-AUG-04-T2 | D18: Implementar la validación de la contraseña actual y la nueva contraseña.
C19: =CONCATENATE($A$8,"-",B17,"-","T3") -> E01-HU-AUG-04-T3 | D19: Crear la lógica de confirmación del cambio de contraseña con un mensaje de éxito
B20: HU-AUG-05 | C20: =CONCATENATE($A$8,"-",B20,"-","T1") -> E01-HU-AUG-05-T1 | D20: Diseñar la interfaz para que el admin pueda crear una cuenta de usuario. | E20: 6 | F20: SPRINT 1
C21: =CONCATENATE($A$8,"-",B20,"-","T2") -> E01-HU-AUG-05-T2 | D21: Configurar los permisos y roles para cada usuario creado (directiva, personal). | E21: 8
C22: =CONCATENATE($A$8,"-",B20,"-","T3") -> E01-HU-AUG-05-T3 | D22: Implementar la validación de datos para asegurarse de que el nuevo usuario sea creado correctamente. | E22: 6
B23: HU-AUG-06 | C23: =CONCATENATE($A$8,"-",B23,"-","T1") -> E01-HU-AUG-06-T1 | D23: Crear la página de editar perfil donde los usuarios puedan actualizar sus datos.
C24: =CONCATENATE($A$8,"-",B23,"-","T2") -> E01-HU-AUG-06-T2 | D24: Implementar la validación de datos en los campos editables (correo, nombre, etc.).
C25: =CONCATENATE($A$8,"-",B23,"-","T3") -> E01-HU-AUG-06-T3 | D25: Desarrollar la lógica para guardar cambios en la base de datos de manera segura.
B26: HU-AUG-07 | C26: =CONCATENATE($A$8,"-",B26,"-","T1") -> E01-HU-AUG-07-T1 | D26: Crear la funcionalidad para que el admin pueda desactivar cuentas desde el panel de administración.
C27: =CONCATENATE($A$8,"-",B26,"-","T2") -> E01-HU-AUG-07-T2 | D27: Implementar la funcionalidad de reactivación de una cuenta desactivada.
C28: =CONCATENATE($A$8,"-",B26,"-","T3") -> E01-HU-AUG-07-T3 | D28: Validar que las cuentas desactivadas no puedan iniciar sesión hasta ser reactivadas.
B29: HU-AUG-08 | C29: =CONCATENATE($A$8,"-",B29,"-","T1") -> E01-HU-AUG-08-T1 | D29: Crear la opción para que el usuario pueda desactivar su cuenta desde el panel de configuración.
C30: =CONCATENATE($A$8,"-",B29,"-","T2") -> E01-HU-AUG-08-T2 | D30: Desarrollar la funcionalidad de reactivación de la cuenta al iniciar sesión nuevamente.
C31: =CONCATENATE($A$8,"-",B29,"-","T3") -> E01-HU-AUG-08-T3 | D31: Implementar un mensaje de confirmación al desactivar la cuenta.
B32: HU-AUG-09 | C32: =CONCATENATE($A$8,"-",B32,"-","T1") -> E01-HU-AUG-09-T1 | D32: Desarrollar la página para que el admin vea el listado completo de usuarios registrados.
C33: =CONCATENATE($A$8,"-",B32,"-","T2") -> E01-HU-AUG-09-T2 | D33: Implementar filtros para visualizar usuarios por estado (activo/desactivado) y rol.
C34: =CONCATENATE($A$8,"-",B32,"-","T3") -> E01-HU-AUG-09-T3 | D34: Crear una funcionalidad para editar o eliminar usuarios desde la lista.
A35: E02 | B35: HU-CR-01 | C35: =CONCATENATE($A$35,"-",B35,"-","T1") -> E02-HU-CR-01-T1 | D35: Crear una interfaz para que el socio pueda acceder al formulario de solicitud de certificado. | E35: 6 | F35: SPRINT 1
C36: =CONCATENATE($A$35,"-",B35,"-","T2") -> E02-HU-CR-01-T2 | D36: Implementar la validación de los campos requeridos en el formulario. | E36: 6
C37: =CONCATENATE($A$35,"-",B35,"-","T3") -> E02-HU-CR-01-T3 | D37: Desarrollar el proceso de envío de solicitud a la base de datos. | E37: 8
B38: HU-CR-02 | C38: =CONCATENATE($A$35,"-",B38,"-","T1") -> E02-HU-CR-02-T1 | D38: Desarrollar el formulario con los campos necesarios: nombre, RUT, dirección. | E38: 6
C39: =CONCATENATE($A$35,"-",B38,"-","T2") -> E02-HU-CR-02-T2 | D39: Implementar validación de los datos para asegurar que la información esté completa y correcta. | E39: 8
C40: =CONCATENATE($A$35,"-",B38,"-","T3") -> E02-HU-CR-02-T3 | D40: Crear un sistema de confirmación que notifique al usuario que el formulario ha sido enviado correctamente. | E40: 6
B41: HU-CR-03 | C41: =CONCATENATE($A$35,"-",B41,"-","T1") -> E02-HU-CR-03-T1 | D41: Crear la lógica para validar el RUT y otros datos personales.
C42: =CONCATENATE($A$35,"-",B41,"-","T2") -> E02-HU-CR-03-T2 | D42: Implementar la validación en tiempo real mientras el usuario completa el formulario.
...

Sheet Sprint_Planning
A2: Duración Sprint (2 semanas)
A5: Sprint 1 | D5: ID Historia de usuario | E5: Historia de usuario | F5: Planning Poker
D6: HU-AUG-01 | E6: Registro de usuario (Socio) | F6: 3
D7: HU-AUG-02 | E7: Inicio de sesión | F7: 2 | H7: Segun el esfuerzo del equipo, el primer sprint contemplara estas historias de usuario
D8: HU-AUG-05 | E8: Crear cuenta de usuario (Sistema) | F8: 5
D9: HU-CR-01 | E9: Solicitar certificado | F9: 3
D10: HU-CR-02 | E10: Completar formulario de certificado | F10: 3
D11: HU-PG-01 | E11: Integración con pasarela de pago | F11: 13
D12: HU-PG-02 | E12: Checkout seguro y retorno | F12: 5
D13: HU-PG-03 | E13: Actualización por webhook/callback | F13: 5
D14: HU-PG-04 | E14: Confirmación automática condicionada al pago | F14: 3
D15: HU-PG-05 | E15: Comprobante digital | F15: 3
D16: HU-CR-04 | E16: Pago del certificado | F16: 8
D17: HU-CR-05 | E17: Emisión de certificado | F17: 3
D18: HU-RE-01 | E18: Reservar espacio comunitario | F18: 12
D19: HU-RE-03 | E19: Pago de la reserva | F19: 13
A21: Sprint 2 | D21: ID Historia de usuario | E21: Historia de usuario | F21: Planning Poker
D22: HU-AUG-01 | E22: Registro de usuario (Socio) | F22: 3
D23: HU-AUG-02 | E23: Inicio de sesión | F23: 2
D24: HU-AUG-05 | E24: Crear cuenta de usuario (Sistema) | F24: 5
D25: HU-CR-01 | E25: Solicitar certificado | F25: 3
D26: HU-CR-02 | E26: Completar formulario de certificado | F26: 3
D27: HU-PG-01 | E27: Integración con pasarela de pago | F27: 13
D28: HU-PG-02 | E28: Checkout seguro y retorno | F28: 5
D29: HU-PG-03 | E29: Actualización por webhook/callback | F29: 5 | H29: Segun el esfuerzo del equipo, el segundo sprint contemplara estas historias de usuario
D30: HU-PG-04 | E30: Confirmación automática condicionada al pago | F30: 3
D31: HU-PG-05 | E31: Comprobante digital | F31: 3
D32: HU-CR-04 | E32: Pago del certificado | F32: 8
D33: HU-CR-05 | E33: Emisión de certificado | F33: 3
D34: HU-RE-01 | E34: Reservar espacio comunitario | F34: 12
D35: HU-RE-03 | E35: Pago de la reserva | F35: 13
A37: Sprint 3 | D37: ID Historia de usuario | E37: Historia de usuario | F37: Planning Poker
D38: HU-AUG-01 | E38: Registro de usuario (Socio) | F38: 3
D39: HU-AUG-02 | E39: Inicio de sesión | F39: 2
D40: HU-AUG-05 | E40: Crear cuenta de usuario (Sistema) | F40: 5
D41: HU-CR-01 | E41: Solicitar certificado | F41: 3
D42: HU-CR-02 | E42: Completar formulario de certificado | F42: 3
D43: HU-PG-01 | E43: Integración con pasarela de pago | F43: 13
D44: HU-PG-02 | E44: Checkout seguro y retorno | F44: 5
D45: HU-PG-03 | E45: Actualización por webhook/callback | F45: 5
...

Sheet Sprint_Backlog
A1: Metodologías ágiles: Lista de tareas de la iteración
A2: (Sprint Backlog)
A3: Elaborado por: pmoinformatica.com
G4: Día 1 | J4: Día 2 | M4: Día 3 | P4: Día 4 | S4: Día 5 | V4: Día 6 | Y4: Día 7 | AB4: Día 8 | AE4: Día 9 | AH4: Día 10 | AK4: Día 11 | AN4: Día 12 | AQ4: Día 13 | AT4: Día 14 | AW4: Día 15 | AZ4: Día 16 | BC4: Día 17 | BF4: Día 18 | BI4: Día 19 | BL4: Día 20 | BO4: Total
A5: Identificador (ID) de item de product backlog | B5: Enunciado del item de Product Backlog | C5: Tarea | D5: Dueño / Voluntario | E5: Estatus | F5: Horas estimadas totales | G5: Cons. | H5: Rest. | J5: Cons. | K5: Rest. | M5: Cons. | N5: Rest. | P5: Cons. | Q5: Rest. | S5: Cons. | T5: Rest. | V5: Cons. | W5: Rest. | Y5: Cons. | Z5: Rest. | AB5: Cons. | AC5: Rest. | AE5: Cons. | AF5: Rest. | AH5: Cons. | AI5: Rest. | AK5: Cons. | AL5: Rest. | AN5: Cons. | AO5: Rest. | AQ5: Cons. | AR5: Rest. | AT5: Cons. | AU5: Rest. | AW5: Cons. | AX5: Rest. | AZ5: Cons. | BA5: Rest. | BC5: Cons. | BD5: Rest. | BF5: Cons. | BG5: Rest. | BI5: Cons. | BJ5: Rest. | BL5: Cons. | BM5: Rest. | BO5: Cons. | BP5: Rest.
A6: =Product_Backlog_tareas!C8 -> E01-HU-AUG-01-T1 | B6: Registro de usuario (Socio) | C6: Diseñar y validar el formulario de registro (campos: nombre, RUT, dirección, correo) | D6: Alex Mazuela | E6: Completo | F6: 6
A7: =Product_Backlog_tareas!C9 -> E01-HU-AUG-01-T2 | B7: Registro de usuario (Socio) | C7: Implementar la validación del RUT y correo electrónico para evitar errores. | D7: Alex Mazuela | E7: Completo | F7: 8
A8: =Product_Backlog_tareas!C10 -> E01-HU-AUG-01-T3 | B8: Registro de usuario (Socio) | C8: Desarrollar la funcionalidad para enviar un correo de confirmación con el enlace de activación. | D8: Alex Mazuela | E8: Completo | F8: 10
A9: =Product_Backlog_tareas!C11 -> E01-HU-AUG-02-T1 | B9: Inicio de sesión | C9: Crear el formulario de inicio de sesión con campos para correo y contraseña. | D9: Javiera Azúa | E9: Completo | F9: 4
A10: =Product_Backlog_tareas!C12 -> E01-HU-AUG-02-T2 | B10: Inicio de sesión | C10: Implementar la validación de credenciales en el backend. | D10: Javiera Azúa | E10: Completo | F10: 8
A11: =Product_Backlog_tareas!C13 -> E01-HU-AUG-02-T3 | B11: Inicio de sesión | C11: Crear la lógica para redirigir a los usuarios al panel de usuario tras un inicio de sesión exitoso | D11: Javiera Azúa | E11: Completo | F11: 6
A12: =Product_Backlog_tareas!C20 -> E01-HU-AUG-05-T1 | B12: Crear cuenta de usuario (Sistema) | C12: Diseñar la interfaz para que el admin pueda crear una cuenta de usuario. | D12: Alex Mazuela | E12: Completo | F12: 6
A13: =Product_Backlog_tareas!C21 -> E01-HU-AUG-05-T2 | B13: Crear cuenta de usuario (Sistema) | C13: Configurar los permisos y roles para cada usuario creado (directiva, personal). | D13: Alex Mazuela | E13: Completo | F13: 8
A14: =Product_Backlog_tareas!C22 -> E01-HU-AUG-05-T3 | B14: Crear cuenta de usuario (Sistema) | C14: Implementar la validación de datos para asegurarse de que el nuevo usuario sea creado correctamente. | D14: Alex Mazuela | E14: Completo | F14: 6
A15: =Product_Backlog_tareas!C35 -> E02-HU-CR-01-T1 | B15: Solicitar certificado | C15: Crear una interfaz para que el socio pueda acceder al formulario de solicitud de certificado. | D15: Javiera Azúa | E15: Completo | F15: 6
A16: =Product_Backlog_tareas!C36 -> E02-HU-CR-01-T2 | B16: Solicitar certificado | C16: Implementar la validación de los campos requeridos en el formulario. | D16: Javiera Azúa | E16: Completo | F16: 6
A17: =Product_Backlog_tareas!C37 -> E02-HU-CR-01-T3 | B17: Solicitar certificado | C17: Desarrollar el proceso de envío de solicitud a la base de datos. | D17: Javiera Azúa | E17: Completo | F17: 8
A18: =Product_Backlog_tareas!C38 -> E02-HU-CR-02-T1 | B18: Completar formulario de certificado | C18: Desarrollar el formulario con los campos necesarios: nombre, RUT, dirección. | D18: Alex Mazuela | E18: Completo | F18: 6
A19: =Product_Backlog_tareas!C39 -> E02-HU-CR-02-T2 | B19: Completar formulario de certificado | C19: Implementar validación de los datos para asegurar que la información esté completa y correcta. | D19: Alex Mazuela | E19: Completo | F19: 8
A20: =Product_Backlog_tareas!C40 -> E02-HU-CR-02-T3 | B20: Completar formulario de certificado | C20: Crear un sistema de confirmación que notifique al usuario que el formulario ha sido enviado correctamente. | D20: Alex Mazuela | E20: Completo | F20: 6
